Workbook

Sheet Resumo
A1: Resumo financeiro — VIA LEITE SENSE Saúde (controle interno)
A3: Capital (subvenção) | B3: =SUMIFS(Despesas!J2:J39,Despesas!B2:B39,"Subvenção",Despesas!C2:C39,"Capital")
A4: Custeio (subvenção) | B4: =SUMIFS(Despesas!J2:J39,Despesas!B2:B39,"Subvenção",Despesas!C2:C39,"Custeio")
A5: TOTAL SUBVENÇÃO | B5: =B3+B4 | C5: =IF(B5=60000.0,"Utiliza 100% do limite","DIVERGE DO LIMITE")
A6: 1ª parcela — meses 1 a 6 (subvenção) | B6: =SUMIFS(Despesas!J2:J39,Despesas!B2:B39,"Subvenção",Despesas!D2:D39,"1ª") | C6: =IF(B6=30000.0,"OK — R$ 30 mil","DIVERGE")
A7: 2ª parcela — meses 7 a 12 (subvenção) | B7: =SUMIFS(Despesas!J2:J39,Despesas!B2:B39,"Subvenção",Despesas!D2:D39,"2ª") | C7: =IF(B7=30000.0,"OK — R$ 30 mil","DIVERGE")
A8: Contrapartida | B8: =SUMIF(Despesas!B2:B39,"Contrapartida",Despesas!J2:J39) | C8: =IF(B8>=60000.0*10%,"DENTRO DO LIMITE MÍNIMO EXIGIDO","ABAIXO DE 10%")
A9: TOTAL DO PROJETO | B9: =B5+B8

Sheet Despesas
A1: ID | B1: Fonte | C1: Natureza | D1: Parcela | E1: Rubrica | F1: Item | G1: Especificação | H1: Qtd | I1: Vl unitário | J1: Total | K1: Objetivo(s) | L1: Meses | M1: Justificativa | N1: Orçamento 1 | O1: Orçamento 2 | P1: Orçamento 3
A2: C1 | B2: Subvenção | C2: Capital | D2: 1ª | E2: CAPITAL: Aquisição de máquinas, equipamentos, aparelhos e utensílios | F2: Computador portátil para desenvolvimento e ciência de dados | G2: Processador de 8 núcleos/16 threads ou superior; 32 GB de RAM; SSD NVMe 1 TB; GPU dedicada com 8 GB; tela 15,6". | H2: 1 | I2: 8500 | J2: =H2*I2 | K2: 2, 3 e 5 | L2: M1 | M2: Uso exclusivo no projeto para compilar o firmware dos protótipos, rodar o ambiente de testes e treinar e recalibrar os modelos com as séries de telemetria das propriedades. Os equipamentos pessoais da equipe não comportam o treinamento com dados de alta frequência. Vinculado aos objetivos específicos 2, 3 e 5; aquisição no mês 1 (1ª parcela).
A3: C2 | B3: Subvenção | C3: Capital | D3: 1ª | E3: CAPITAL: Aquisição de máquinas, equipamentos, aparelhos e utensílios | F3: Estação de solda com controle digital de temperatura | G3: Potência ≥ 60 W, faixa 200–480 °C, com suporte e esponja. | H3: 1 | I3: 700 | J3: =H3*I3 | K3: 2 | L3: M1 | M3: Montagem dos protótipos e das unidades de campo (soldagem de sensores, conectores e placas) e reparos durante o piloto. Vinculado ao objetivo específico 2; aquisição no mês 1 (1ª parcela).
A4: C3 | B4: Subvenção | C4: Capital | D4: 1ª | E4: CAPITAL: Aquisição de máquinas, equipamentos, aparelhos e utensílios | F4: Multímetro digital true RMS | G4: Categoria CAT III 600 V; mede tensão, corrente, resistência, continuidade e temperatura. | H4: 1 | I4: 450 | J4: =H4*I4 | K4: 2 e 4 | L4: M1 | M4: Verificação de alimentação, consumo em bateria e diagnóstico de falhas na bancada e na instalação em campo. Vinculado aos objetivos específicos 2 e 4; aquisição no mês 1 (1ª parcela).
A5: C4 | B5: Subvenção | C5: Capital | D5: 1ª | E5: CAPITAL: Aquisição de máquinas, equipamentos, aparelhos e utensílios | F5: Fonte de alimentação de bancada regulável | G5: Saída 0–30 V / 0–5 A, com ajuste fino e indicação digital de tensão e corrente. | H5: 1 | I5: 650 | J5: =H5*I5 | K5: 2 | L5: M1 | M5: Ensaios de consumo, simulação de queda e retorno de energia e teste de autonomia em bateria, exigidos pelo critério de aceite dos protótipos. Vinculado ao objetivo específico 2; aquisição no mês 1 (1ª parcela).
A6: C5 | B6: Subvenção | C6: Capital | D6: 1ª | E6: CAPITAL: Aquisição de máquinas, equipamentos, aparelhos e utensílios | F6: Impressora 3D de fabricação por filamento fundido | G6: Área de impressão ≥ 250 × 250 × 250 mm; mesa aquecida ≥ 100 °C; câmara fechada; nivelamento automático; compatível com PETG e ASA. | H6: 1 | I6: 5500 | J6: =H6*I6 | K6: 2 e 4 | L6: M2 | M6: Fabricação dos gabinetes estanques, suportes de sonda e abrigos de radiação das microestações, sob medida para cada tanque e curral, com iteração rápida do desenho após os ensaios e reposição de peças no piloto. A câmara fechada é necessária para o ASA, resistente a UV e a produtos de limpeza. Vinculado aos objetivos específicos 2 e 4; aquisição no mês 2 (1ª parcela).
A7: C6 | B7: Subvenção | C7: Capital | D7: 1ª | E7: CAPITAL: Aquisição de máquinas, equipamentos, aparelhos e utensílios | F7: Computador de borda (gateway) — prova de conceito | G7: computador de placa única 64 bits, 4 núcleos, 8 GB de RAM, com gabinete com dissipação ativa, fonte de 27 W e cartão de memória industrial de 32 GB. | H7: 1 | I7: 1100 | J7: =H7*I7 | K7: 2 | L7: M3 | M7: Recebe os dados dos sensores na propriedade da prova de conceito, armazena durante quedas de internet e sincroniza com a nuvem, para que nenhuma leitura se perca justamente durante o evento que o sistema precisa detectar. Vinculado ao objetivo específico 2; aquisição no mês 3 (1ª parcela).
A8: C7 | B8: Subvenção | C8: Capital | D8: 1ª | E8: CAPITAL: Aquisição de máquinas, equipamentos, aparelhos e utensílios | F8: Roteador 4G com antena externa — prova de conceito | G8: roteador LTE categoria 4 com slot para chip, Wi-Fi e porta Ethernet, com antena externa de 9 dBi, cabo de 5 m e suporte de mastro. | H8: 1 | I8: 750 | J8: =H8*I8 | K8: 2 | L8: M3 | M8: Enlace entre o gateway e a nuvem na propriedade da prova de conceito, em área rural com sinal fraco; a antena externa viabiliza a entrega de dados ≥ 95%. Vinculado ao objetivo específico 2; aquisição no mês 3 (1ª parcela).
A9: C8 | B9: Subvenção | C9: Capital | D9: 1ª | E9: CAPITAL: Aquisição de máquinas, equipamentos, aparelhos e utensílios | F9: Registrador de temperatura de referência — bancada e prova de conceito | G9: registrador autônomo de temperatura com sonda externa, faixa −40 a +85 °C, resolução 0,1 °C, memória ≥ 16.000 leituras, USB, com certificado de calibração. | H9: 2 | I9: 450 | J9: =H9*I9 | K9: 2 | L9: M3 | M9: Medição independente em paralelo aos protótipos, na bancada e no tanque, para comprovar o desvio ≤ 0,5 °C. Sem a segunda medição o teste afirma que o sensor funciona; com ela, demonstra. Vinculado ao objetivo específico 2; aquisição no mês 3 (1ª parcela).
A10: C9 | B10: Subvenção | C10: Capital | D10: 2ª | E10: CAPITAL: Aquisição de máquinas, equipamentos, aparelhos e utensílios | F10: Computadores de borda (gateways) — piloto | G10: computador de placa única 64 bits, 4 núcleos, 8 GB de RAM, com gabinete com dissipação ativa, fonte de 27 W e cartão de memória industrial de 32 GB. | H10: 4 | I10: 1100 | J10: =H10*I10 | K10: 4 | L10: M7 | M10: Um para cada uma das outras 4 propriedades do piloto, com a mesma função do gateway da prova de conceito. Vinculado ao objetivo específico 4; aquisição no mês 7 (2ª parcela).
A11: C10 | B11: Subvenção | C11: Capital | D11: 2ª | E11: CAPITAL: Aquisição de máquinas, equipamentos, aparelhos e utensílios | F11: Roteadores 4G com antena externa — piloto | G11: roteador LTE categoria 4 com slot para chip, Wi-Fi e porta Ethernet, com antena externa de 9 dBi, cabo de 5 m e suporte de mastro. | H11: 4 | I11: 750 | J11: =H11*I11 | K11: 4 | L11: M7 | M11: Um para cada uma das outras 4 propriedades do piloto, condição para a disponibilidade de dados ≥ 95% exigida no piloto. Vinculado ao objetivo específico 4; aquisição no mês 7 (2ª parcela).
A12: C11 | B12: Subvenção | C12: Capital | D12: 2ª | E12: CAPITAL: Aquisição de máquinas, equipamentos, aparelhos e utensílios | F12: Registradores de temperatura de referência — piloto | G12: registrador autônomo de temperatura com sonda externa, faixa −40 a +85 °C, resolução 0,1 °C, memória ≥ 16.000 leituras, USB, com certificado de calibração. | H12: 4 | I12: 450 | J12: =H12*I12 | K12: 4 e 5 | L12: M7 | M12: Medição independente nos tanques das demais propriedades, para conferir a temperatura do leite durante todo o piloto. Vinculado aos objetivos específicos 4 e 5; aquisição no mês 7 (2ª parcela).
A13: K1 | B13: Subvenção | C13: Custeio | D13: 1ª | E13: CUSTEIO: Serviços de terceiros de pessoa física e/ou jurídica de caráter eventual | F13: Hospedagem em nuvem da plataforma — meses 1 a 6 | G13: Servidor de aplicação, banco de dados gerenciado, broker MQTT e backup diário (6 meses × R$ 300,00). | H13: 6 | I13: 300 | J13: =H13*I13 | K13: 2 e 3 | L13: M1, M2, M3, M4, M5, M6 | M13: Infraestrutura que recebe a telemetria dos protótipos, executa o motor de risco e hospeda o ambiente de desenvolvimento do Módulo de Saúde do Rebanho. Vinculado aos objetivos específicos 2 e 3; aquisição nos meses 1 a 6 (1ª parcela).
... A39: P4 | B39: Contrapartida | C39: Custeio | D39: 2ª | E39: CUSTEIO: Serviços de terceiros de pessoa física e/ou jurídica de caráter eventual | F39: Serviço de contabilidade para a gestão financeira do projeto — meses 7 a 12 | G39: Escrituração, conciliação da conta do projeto e apoio à prestação de contas final (6 meses × R$ 250,00). | H39: 6 | I39: 250 | J39: =H39*I39 | K39: todos | L39: M7, M8, M9, M10, M11, M12 | M39: Assegura a comprovação fiscal e a prestação de contas final do projeto. Vinculado a todos os objetivos específicos; aquisição nos meses 7 a 12 (2ª parcela).

Sheet Desembolso mensal
A1: ID | B1: Item | C1: Fonte | D1: M1 | E1: M2 | F1: M3 | G1: M4 | H1: M5 | I1: M6 | J1: M7 | K1: M8 | L1: M9 | M1: M10 | N1: M11 | O1: M12 | P1: Total | Q1: Confere
A2: C1 | B2: Computador portátil para desenvolvimento e ciência de dados | C2: Subvenção | D2: 8500 | P2: =SUM(D2:O2) | Q2: =IF(ROUND(P2-SUMIF(Despesas!A:A,A2,Despesas!J:J),2)=0,"OK","DIVERGE")
A3: C2 | B3: Estação de solda com controle digital de temperatura | C3: Subvenção | D3: 700 | P3: =SUM(D3:O3) | Q3: =IF(ROUND(P3-SUMIF(Despesas!A:A,A3,Despesas!J:J),2)=0,"OK","DIVERGE")
A4: C3 | B4: Multímetro digital true RMS | C4: Subvenção | D4: 450 | P4: =SUM(D4:O4) | Q4: =IF(ROUND(P4-SUMIF(Despesas!A:A,A4,Despesas!J:J),2)=0,"OK","DIVERGE")
A5: C4 | B5: Fonte de alimentação de bancada regulável | C5: Subvenção | D5: 650 | P5: =SUM(D5:O5) | Q5: =IF(ROUND(P5-SUMIF(Despesas!A:A,A5,Despesas!J:J),2)=0,"OK","DIVERGE")
A6: C5 | B6: Impressora 3D de fabricação por filamento fundido | C6: Subvenção | E6: 5500 | P6: =SUM(D6:O6) | Q6: =IF(ROUND(P6-SUMIF(Despesas!A:A,A6,Despesas!J:J),2)=0,"OK","DIVERGE")
A7: C6 | B7: Computador de borda (gateway) — prova de conceito | C7: Subvenção | F7: 1100 | P7: =SUM(D7:O7) | Q7: =IF(ROUND(P7-SUMIF(Despesas!A:A,A7,Despesas!J:J),2)=0,"OK","DIVERGE")
A8: C7 | B8: Roteador 4G com antena externa — prova de conceito | C8: Subvenção | F8: 750 | P8: =SUM(D8:O8) | Q8: =IF(ROUND(P8-SUMIF(Despesas!A:A,A8,Despesas!J:J),2)=0,"OK","DIVERGE")
A9: C8 | B9: Registrador de temperatura de referência — bancada e prova de conceito | C9: Subvenção | F9: 900 | P9: =SUM(D9:O9) | Q9: =IF(ROUND(P9-SUMIF(Despesas!A:A,A9,Despesas!J:J),2)=0,"OK","DIVERGE")
A10: C9 | B10: Computadores de borda (gateways) — piloto | C10: Subvenção | J10: 4400 | P10: =SUM(D10:O10) | Q10: =IF(ROUND(P10-SUMIF(Despesas!A:A,A10,Despesas!J:J),2)=0,"OK","DIVERGE")
A11: C10 | B11: Roteadores 4G com antena externa — piloto | C11: Subvenção | J11: 3000 | P11: =SUM(D11:O11) | Q11: =IF(ROUND(P11-SUMIF(Despesas!A:A,A11,Despesas!J:J),2)=0,"OK","DIVERGE")
A12: C11 | B12: Registradores de temperatura de referência — piloto | C12: Subvenção | J12: 1800 | P12: =SUM(D12:O12) | Q12: =IF(ROUND(P12-SUMIF(Despesas!A:A,A12,Despesas!J:J),2)=0,"OK","DIVERGE")
A13: K1 | B13: Hospedagem em nuvem da plataforma — meses 1 a 6 | C13: Subvenção | D13: 300 | E13: 300 | F13: 300 | G13: 300 | H13: 300 | I13: 300 | P13: =SUM(D13:O13) | Q13: =IF(ROUND(P13-SUMIF(Despesas!A:A,A13,Despesas!J:J),2)=0,"OK","DIVERGE")
A14: K2 | B14: Combustível para deslocamentos — meses 1 a 6 | C14: Subvenção | D14: 504 | E14: 252 | G14: 378 | I14: 378 | P14: =SUM(D14:O14) | Q14: =IF(ROUND(P14-SUMIF(Despesas!A:A,A14,Despesas!J:J),2)=0,"OK","DIVERGE")
A15: K3 | B15: Componentes eletrônicos dos nós de tanque — protótipos | C15: Subvenção | E15: 1900 | P15: =SUM(D15:O15) | Q15: =IF(ROUND(P15-SUMIF(Despesas!A:A,A15,Despesas!J:J),2)=0,"OK","DIVERGE")
A16: K4 | B16: Componentes da microestação de THI — protótipo | C16: Subvenção | E16: 300 | P16: =SUM(D16:O16) | Q16: =IF(ROUND(P16-SUMIF(Despesas!A:A,A16,Despesas!J:J),2)=0,"OK","DIVERGE")
A17: K5 | B17: Filamento para impressão 3D (PETG e ASA) | C17: Subvenção | E17: 750 | F17: 750 | P17: =SUM(D17:O17) | Q17: =IF(ROUND(P17-SUMIF(Despesas!A:A,A17,Despesas!J:J),2)=0,"OK","DIVERGE")
A18: K6 | B18: Consumíveis de prototipagem eletrônica | C18: Subvenção | E18: 688 | P18: =SUM(D18:O18) | Q18: =IF(ROUND(P18-SUMIF(Despesas!A:A,A18,Despesas!J:J),2)=0,"OK","DIVERGE")
A19: K7 | B19: Material de instalação sanitária dos nós de tanque — protótipos | C19: Subvenção | F19: 800 | P19: =SUM(D19:O19) | Q19: =IF(ROUND(P19-SUMIF(Despesas!A:A,A19,Despesas!J:J),2)=0,"OK","DIVERGE")
A20: K8 | B20: Calibração rastreável (RBC) das sondas dos protótipos | C20: Subvenção | G20: 400 | P20: =SUM(D20:O20) | Q20: =IF(ROUND(P20-SUMIF(Despesas!A:A,A20,Despesas!J:J),2)=0,"OK","DIVERGE")
A21: K9 | B21: Serviço de mensageria (API de mensagens) — meses 5 e 6 | C21: Subvenção | H21: 150 | I21: 150 | P21: =SUM(D21:O21) | Q21: =IF(ROUND(P21-SUMIF(Despesas!A:A,A21,Despesas!J:J),2)=0,"OK","DIVERGE")
A22: K10 | B22: Reagente para California Mastitis Test (CMT) — linha de base | C22: Subvenção | I22: 330 | P22: =SUM(D22:O22) | Q22: =IF(ROUND(P22-SUMIF(Despesas!A:A,A22,Despesas!J:J),2)=0,"OK","DIVERGE")
A23: K11 | B23: Raquete (bandeja) para CMT | C23: Subvenção | I23: 270 | P23: =SUM(D23:O23) | Q23: =IF(ROUND(P23-SUMIF(Despesas!A:A,A23,Despesas!J:J),2)=0,"OK","DIVERGE")
A24: K12 | B24: Caixa térmica para transporte de amostras de leite | C24: Subvenção | I24: 450 | P24: =SUM(D24:O24) | Q24: =IF(ROUND(P24-SUMIF(Despesas!A:A,A24,Despesas!J:J),2)=0,"OK","DIVERGE")
A25: K13 | B25: Análises laboratoriais de CCS — linha de base | C25: Subvenção | I25: 1200 | P25: =SUM(D25:O25) | Q25: =IF(ROUND(P25-SUMIF(Despesas!A:A,A25,Despesas!J:J),2)=0,"OK","DIVERGE")
A26: K14 | B26: Componentes eletrônicos dos nós de tanque — piloto | C26: Subvenção | J26: 3800 | P26: =SUM(D26:O26) | Q26: =IF(ROUND(P26-SUMIF(Despesas!A:A,A26,Despesas!J:J),2)=0,"OK","DIVERGE")
A27: K15 | B27: Material de instalação sanitária dos nós de tanque — piloto | C27: Subvenção | J27: 1600 | P27: =SUM(D27:O27) | Q27: =IF(ROUND(P27-SUMIF(Despesas!A:A,A27,Despesas!J:J),2)=0,"OK","DIVERGE")
A28: K16 | B28: Componentes das microestações de THI — piloto | C28: Subvenção | J28: 1200 | P28: =SUM(D28:O28) | Q28: =IF(ROUND(P28-SUMIF(Despesas!A:A,A28,Despesas!J:J),2)=0,"OK","DIVERGE")
A29: K17 | B29: Calibração rastreável (RBC) das sondas do piloto | C29: Subvenção | J29: 800 | P29: =SUM(D29:O29) | Q29: =IF(ROUND(P29-SUMIF(Despesas!A:A,A29,Despesas!J:J),2)=0,"OK","DIVERGE")
A30: K18 | B30: Reagente para California Mastitis Test (CMT) — piloto | C30: Subvenção | J30: 330 | P30: =SUM(D30:O30) | Q30: =IF(ROUND(P30-SUMIF(Despesas!A:A,A30,Despesas!J:J),2)=0,"OK","DIVERGE")
A31: K19 | B31: Cartilha impressa de resposta aos alertas | C31: Subvenção | J31: 1190 | P31: =SUM(D31:O31) | Q31: =IF(ROUND(P31-SUMIF(Despesas!A:A,A31,Despesas!J:J),2)=0,"OK","DIVERGE")
A32: K20 | B32: Análises laboratoriais de CCS e CBT — piloto | C32: Subvenção | J32: 1440 | K32: 1440 | L32: 1320 | M32: 1200 | P32: =SUM(D32:O32) | Q32: =IF(ROUND(P32-SUMIF(Despesas!A:A,A32,Despesas!J:J),2)=0,"OK","DIVERGE")
A33: K21 | B33: Hospedagem em nuvem da plataforma — meses 7 a 12 | C33: Subvenção | J33: 300 | K33: 300 | L33: 300 | M33: 300 | N33: 300 | O33: 300 | P33: =SUM(D33:O33) | Q33: =IF(ROUND(P33-SUMIF(Despesas!A:A,A33,Despesas!J:J),2)=0,"OK","DIVERGE")
A34: K22 | B34: Serviço de mensageria (API de mensagens) — meses 7 a 12 | C34: Subvenção | J34: 150 | K34: 150 | L34: 150 | M34: 150 | N34: 150 | O34: 150 | P34: =SUM(D34:O34) | Q34: =IF(ROUND(P34-SUMIF(Despesas!A:A,A34,Despesas!J:J),2)=0,"OK","DIVERGE")
A35: K23 | B35: Combustível para deslocamentos — meses 7 a 12 | C35: Subvenção | J35: 945 | K35: 630 | L35: 630 | M35: 630 | N35: 315 | O35: 630 | P35: =SUM(D35:O35) | Q35: =IF(ROUND(P35-SUMIF(Despesas!A:A,A35,Despesas!J:J),2)=0,"OK","DIVERGE")
A36: P1 | B36: Consultoria jurídica em proteção de dados (LGPD) | C36: Contrapartida | D36: 2000 | P36: =SUM(D36:O36) | Q36: =IF(ROUND(P36-SUMIF(Despesas!A:A,A36,Despesas!J:J),2)=0,"OK","DIVERGE")
A37: P2 | B37: Serviço de contabilidade para a gestão financeira do projeto — meses 1 a 6 | C37: Contrapartida | D37: 250 | E37: 250 | F37: 250 | G37: 250 | H37: 250 | I37: 250 | P37: =SUM(D37:O37) | Q37: =IF(ROUND(P37-SUMIF(Despesas!A:A,A37,Despesas!J:J),2)=0,"OK","DIVERGE")
A38: P3 | B38: Equipamentos de proteção descartáveis para acesso à sala de ordenha | C38: Contrapartida | J38: 1000 | P38: =SUM(D38:O38) | Q38: =IF(ROUND(P38-SUMIF(Despesas!A:A,A38,Despesas!J:J),2)=0,"OK","DIVERGE")
A39: P4 | B39: Serviço de contabilidade para a gestão financeira do projeto — meses 7 a 12 | C39: Contrapartida | J39: 250 | K39: 250 | L39: 250 | M39: 250 | N39: 250 | O39: 250 | P39: =SUM(D39:O39) | Q39: =IF(ROUND(P39-SUMIF(Despesas!A:A,A39,Despesas!J:J),2)=0,"OK","DIVERGE")
B40: Subvenção por mês | D40: =SUMIF($C$2:$C$39,"Subvenção",D2:D39) | E40: =SUMIF($C$2:$C$39,"Subvenção",E2:E39) | F40: =SUMIF($C$2:$C$39,"Subvenção",F2:F39) | G40: =SUMIF($C$2:$C$39,"Subvenção",G2:G39) | H40: =SUMIF($C$2:$C$39,"Subvenção",H2:H39) | I40: =SUMIF($C$2:$C$39,"Subvenção",I2:I39) | J40: =SUMIF($C$2:$C$39,"Subvenção",J2:J39) | K40: =SUMIF($C$2:$C$39,"Subvenção",K2:K39) | ... P40: =SUMIF($C$2:$C$39,"Subvenção",P2:P39)
...

Sheet Objetivos e evidências
A1: Nº | B1: Objetivo específico (com prazo) | C1: Evidência de cumprimento | D1: Status
A2: 1 | B2: Aprovar o protocolo técnico-sanitário e selecionar 5 propriedades leiteiras em Goiás (≥ 120 vacas em lactação), com termo de adesão, consentimento LGPD e linha de base de CCS, CBT e produção dos 3 meses anteriores — até o mês 2. | C2: Protocolo assinado pela RT veterinária; termos de adesão e consentimento; planilha de linha de base. | D2: A iniciar
A3: 2 | B3: Construir 2 protótipos (nó de tanque e microestação de THI), validá-los em bancada e operar um deles por 30 dias em uma propriedade, com desvio ≤ 0,5 °C frente a registrador calibrado, entrega de dados ≥ 95% e recuperação automática após quedas de energia e de rede — até o mês 5. | C3: Relatório de ensaio de bancada; certificado de calibração RBC; 30 dias de série da prova de conceito. | D3: A iniciar
A4: 3 | B4: Entregar o Módulo de Saúde do Rebanho v1.0 com 3 alertas — tendência de CCS (mastite subclínica), estresse térmico por THI local e falha de resfriamento do tanque — enviados por WhatsApp em até 15 minutos, com 100% dos testes críticos aprovados — até o mês 6. | C4: Relatório de testes; registro de versão; demonstração em produção. | D4: A iniciar
A5: 4 | B5: Replicar os kits para as 5 propriedades e operar piloto de campo de 120 dias, com disponibilidade de dados ≥ 95% e ao menos 4 propriedades ativas ao final — meses 7 a 10. | C5: Registros de telemetria; relatório mensal de operação. | D5: A iniciar
A6: 5 | B6: Validar os alertas sanitários contra referência veterinária (linha de base laboratorial no mês 6, CMT quinzenal e 550 análises de CCS/CBT), atingindo sensibilidade ≥ 70% com antecedência ≥ 7 dias sobre o laudo de rotina e precisão ≥ 60% — meses 6 a 11. | C6: Laudos do laboratório credenciado; registro de CMT; planilha de eventos e alertas. | D6: A iniciar
A7: 6 | B7: Capacitar 25 produtores e ordenhadores e 5 técnicos em prevenção de mastite, manejo do estresse térmico e resposta aos alertas, com satisfação média ≥ 4 em escala de 1 a 5 — até o mês 7. | C7: Listas de presença; questionários de avaliação; cartilha. | D7: A iniciar
A8: 7 | B8: Reduzir em ≥ 15% a CCS média de tanque das propriedades piloto em relação à linha de base e firmar ≥ 2 cartas de intenção com laticínios ou cooperativas para adoção do módulo — até o mês 12. | C8: Laudos de tanque antes e depois; cartas de intenção assinadas; relatório final. | D8: A iniciar
